<?xml version="1.0" ?>
<!-- =================================================================================== -->
<!-- |    This document was autogenerated by xacro from gem_1kg_LiDAR.xacro            | -->
<!-- |    EDITING THIS FILE BY HAND IS NOT RECOMMENDED                                 | -->
<!-- =================================================================================== -->
<robot name="gem" xmlns:xacro="http://www.ros.org/wiki/xacro">
  <!-- Macros End -->
  <!-- Base link -->
  <link name="base_link">
    <visual>
      <geometry>
        <box size="0.01 0.01 0.01"/>
      </geometry>
    </visual>
  </link>
  <!-- Chassis START-->
  <joint name="base_joint" type="fixed">
    <parent link="base_link"/>
    <child link="chassis"/>
  </joint>
  <link name="chassis">
    <collision>
      <origin rpy="0 0 0" xyz="0 0 0.292"/>
      <geometry>
        <box size="1.753 1.067 0.1"/>
      </geometry>
    </collision>
    <visual>
      <origin rpy="0 0 0" xyz="0 0 0.3"/>
      <geometry>
        <box size="1.753 1.067 0.1"/>
      </geometry>
      <material name="orange"/>
    </visual>
    <inertial>
      <mass value="1"/>
      <origin rpy="0 0 0" xyz="0 0 0.3"/>
      <inertia ixx="0.0957074166667" ixy="0" ixz="0" iyy="0.256917416667" iyz="0" izz="0.256917416667"/>
      <!--<inertia ixx="0.4" ixy="0.1" ixz="0.1" iyy="0.4" iyz="0.1" izz="0.2"/>-->
    </inertial>
  </link>
  <gazebo reference="chassis">
    <!--Stiffness -->
    <kp>1000000.0</kp>
    <!--Dampening-->
    <kd>0.1</kd>
    <dampingFactor>0</dampingFactor>
    <material>Gazebo/White</material>
    <selfCollide>true</selfCollide>
    <turnGravityOff>false</turnGravityOff>
    <mu1 value="0.1"/>
    <mu2 value="0.1"/>
    <fdir1 value="0 0 0"/>
  </gazebo>
  <!-- Chassis END -->
  <link name="right_wheel">
    <collision>
      <origin rpy="0 1.5708 1.5708" xyz="0 0 0"/>
      <geometry>
        <cylinder length="0.178" radius="0.292"/>
      </geometry>
    </collision>
    <visual>
      <origin rpy="0 1.5708 1.5708" xyz="0 0 0"/>
      <geometry>
        <cylinder length="0.178" radius="0.292"/>
      </geometry>
      <material name="black"/>
    </visual>
    <inertial>
      <origin rpy="0 1.5708 1.5708" xyz="0 0 0"/>
      <mass value="0.2"/>
      <inertia ixx="0.143738" ixy="0" ixz="0" iyy="0.143738" iyz="0" izz="0.255792"/>
      <!--<inertia ixx="0.23" ixy="0" ixz="0" iyy="0.23" iyz="0" izz="0.4"/>-->
    </inertial>
  </link>
  <gazebo reference="right_wheel">
    <mu1 value="2.0"/>
    <mu2 value="2.0"/>
    <kp value="10000000.0"/>
    <kd value="1.0"/>
    <fdir1 value="0 1 0"/>
    <material>Gazebo/Blue</material>
  </gazebo>
  <link name="right_wheel_assembly">
    <collision>
      <origin rpy="0 1.5708 1.5708" xyz="0 0 0"/>
      <geometry>
        <cylinder length="0.001" radius="0.1"/>
      </geometry>
    </collision>
    <visual>
      <origin rpy="0 1.5708 1.5708" xyz="0 0 0"/>
      <geometry>
        <cylinder length="0.001" radius="0.1"/>
      </geometry>
      <material name="black"/>
    </visual>
    <inertial>
      <origin rpy="0 1.5708 1.5708" xyz="0 0 0"/>
      <mass value="0.2"/>
      <inertia ixx="0.00125004166667" ixy="0" ixz="0" iyy="0.00125004166667" iyz="0" izz="0.0025"/>
      <!--<inertia ixx="0.23" ixy="0" ixz="0" iyy="0.23" iyz="0" izz="0.4"/>-->
    </inertial>
  </link>
  <gazebo reference="right_wheel_assembly">
    <mu1 value="2.0"/>
    <mu2 value="2.0"/>
    <kp value="10000000.0"/>
    <kd value="1.0"/>
    <fdir1 value="0 1 0"/>
    <material>Gazebo/White</material>
  </gazebo>
  <joint name="right_wheel_hinge" type="revolute">
    <parent link="chassis"/>
    <child link="right_wheel_assembly"/>
    <origin rpy="0 0 0" xyz="0.8765 -0.6225 0.292"/>
    <axis rpy="0 0 0" xyz="0 0 1"/>
    <limit effort="100" lower="-1" upper="1" velocity="1"/>
    <dynamics damping="0.0" friction="0.0"/>
  </joint>
  <joint name="right_wheel_rotate" type="continuous">
    <parent link="right_wheel_assembly"/>
    <child link="right_wheel"/>
    <origin rpy="0 0 0" xyz="0.0 -0.089 0.0"/>
    <axis rpy="0 0 0" xyz="0 1 0"/>
    <limit effort="100" velocity="50"/>
    <dynamics damping="0.0" friction="0.0"/>
  </joint>
  <transmission name="trans_right_wheel_hing">
    <type>transmission_interface/SimpleTransmission</type>
    <joint name="right_wheel_hinge">
      <hardwareInterface>hardware_interface/EffortJointInterface</hardwareInterface>
    </joint>
    <actuator name="motor_right_wheel_front">
      <hardwareInterface>hardware_interface/EffortJointInterface</hardwareInterface>
      <mechanicalReduction>1</mechanicalReduction>
    </actuator>
  </transmission>
  <transmission name="trans_right_wheel_rotate">
    <type>transmission_interface/SimpleTransmission</type>
    <joint name="right_wheel_rotate">
      <hardwareInterface>hardware_interface/EffortJointInterface</hardwareInterface>
    </joint>
    <actuator name="motor_right_wheel_rotate">
      <hardwareInterface>hardware_interface/EffortJointInterface</hardwareInterface>
      <mechanicalReduction>1</mechanicalReduction>
    </actuator>
  </transmission>
  <link name="left_wheel">
    <collision>
      <origin rpy="0 1.5708 1.5708" xyz="0 0 0"/>
      <geometry>
        <cylinder length="0.178" radius="0.292"/>
      </geometry>
    </collision>
    <visual>
      <origin rpy="0 1.5708 1.5708" xyz="0 0 0"/>
      <geometry>
        <cylinder length="0.178" radius="0.292"/>
      </geometry>
      <material name="black"/>
    </visual>
    <inertial>
      <origin rpy="0 1.5708 1.5708" xyz="0 0 0"/>
      <mass value="0.2"/>
      <inertia ixx="0.143738" ixy="0" ixz="0" iyy="0.143738" iyz="0" izz="0.255792"/>
      <!--<inertia ixx="0.23" ixy="0" ixz="0" iyy="0.23" iyz="0" izz="0.4"/>-->
    </inertial>
  </link>
  <gazebo reference="left_wheel">
    <mu1 value="2.0"/>
    <mu2 value="2.0"/>
    <kp value="10000000.0"/>
    <kd value="1.0"/>
    <fdir1 value="0 1 0"/>
    <material>Gazebo/Blue</material>
  </gazebo>
  <link name="left_wheel_assembly">
    <collision>
      <origin rpy="0 1.5708 1.5708" xyz="0 0 0"/>
      <geometry>
        <cylinder length="0.001" radius="0.1"/>
      </geometry>
    </collision>
    <visual>
      <origin rpy="0 1.5708 1.5708" xyz="0 0 0"/>
      <geometry>
        <cylinder length="0.001" radius="0.1"/>
      </geometry>
      <material name="black"/>
    </visual>
    <inertial>
      <origin rpy="0 1.5708 1.5708" xyz="0 0 0"/>
      <mass value="0.2"/>
      <inertia ixx="0.00125004166667" ixy="0" ixz="0" iyy="0.00125004166667" iyz="0" izz="0.0025"/>
      <!--<inertia ixx="0.23" ixy="0" ixz="0" iyy="0.23" iyz="0" izz="0.4"/>-->
    </inertial>
  </link>
  <gazebo reference="left_wheel_assembly">
    <mu1 value="2.0"/>
    <mu2 value="2.0"/>
    <kp value="10000000.0"/>
    <kd value="1.0"/>
    <fdir1 value="0 1 0"/>
    <material>Gazebo/White</material>
  </gazebo>
  <joint name="left_wheel_hinge" type="revolute">
    <parent link="chassis"/>
    <child link="left_wheel_assembly"/>
    <origin rpy="0 0 0" xyz="0.8765 0.6225 0.292"/>
    <axis rpy="0 0 0" xyz="0 0 1"/>
    <limit effort="100" lower="-1" upper="1" velocity="1"/>
    <dynamics damping="0.0" friction="0.0"/>
  </joint>
  <joint name="left_wheel_rotate" type="continuous">
    <parent link="left_wheel_assembly"/>
    <child link="left_wheel"/>
    <origin rpy="0 0 0" xyz="0.0 0.089 0.0"/>
    <axis rpy="0 0 0" xyz="0 1 0"/>
    <limit effort="100" velocity="50"/>
    <dynamics damping="0.0" friction="0.0"/>
  </joint>
  <transmission name="trans_left_wheel_hing">
    <type>transmission_interface/SimpleTransmission</type>
    <joint name="left_wheel_hinge">
      <hardwareInterface>hardware_interface/EffortJointInterface</hardwareInterface>
    </joint>
    <actuator name="motor_left_wheel_front">
      <hardwareInterface>hardware_interface/EffortJointInterface</hardwareInterface>
      <mechanicalReduction>1</mechanicalReduction>
    </actuator>
  </transmission>
  <transmission name="trans_left_wheel_rotate">
    <type>transmission_interface/SimpleTransmission</type>
    <joint name="left_wheel_rotate">
      <hardwareInterface>hardware_interface/EffortJointInterface</hardwareInterface>
    </joint>
    <actuator name="motor_left_wheel_rotate">
      <hardwareInterface>hardware_interface/EffortJointInterface</hardwareInterface>
      <mechanicalReduction>1</mechanicalReduction>
    </actuator>
  </transmission>
  <link name="right_wheel_rear">
    <collision>
      <origin rpy="0 1.5708 1.5708" xyz="0 0 0"/>
      <geometry>
        <cylinder length="0.178" radius="0.292"/>
      </geometry>
    </collision>
    <visual>
      <origin rpy="0 1.5708 1.5708" xyz="0 0 0"/>
      <geometry>
        <cylinder length="0.178" radius="0.292"/>
      </geometry>
      <material name="black"/>
    </visual>
    <inertial>
      <origin rpy="0 1.5708 1.5708" xyz="0 0 0"/>
      <mass value="0.2"/>
      <inertia ixx="0.143738" ixy="0" ixz="0" iyy="0.143738" iyz="0" izz="0.255792"/>
      <!--<inertia ixx="0.23" ixy="0" ixz="0" iyy="0.23" iyz="0" izz="0.4"/>-->
    </inertial>
  </link>
  <gazebo reference="right_wheel_rear">
    <mu1 value="2.0"/>
    <mu2 value="2.0"/>
    <kp value="10000000.0"/>
    <kd value="1.0"/>
    <fdir1 value="0 1 0"/>
    <material>Gazebo/Blue</material>
  </gazebo>
  <joint name="right_wheel_rear_rotate" type="continuous">
    <parent link="chassis"/>
    <child link="right_wheel_rear"/>
    <origin rpy="0 0 0" xyz="-0.8765 -0.7115 0.292"/>
    <axis rpy="0 0 0" xyz="0 1 0"/>
    <limit effort="0" velocity="0"/>
    <dynamics damping="0.0" friction="0.0"/>
  </joint>
  <link name="left_wheel_rear">
    <collision>
      <origin rpy="0 1.5708 1.5708" xyz="0 0 0"/>
      <geometry>
        <cylinder length="0.178" radius="0.292"/>
      </geometry>
    </collision>
    <visual>
      <origin rpy="0 1.5708 1.5708" xyz="0 0 0"/>
      <geometry>
        <cylinder length="0.178" radius="0.292"/>
      </geometry>
      <material name="black"/>
    </visual>
    <inertial>
      <origin rpy="0 1.5708 1.5708" xyz="0 0 0"/>
      <mass value="0.2"/>
      <inertia ixx="0.143738" ixy="0" ixz="0" iyy="0.143738" iyz="0" izz="0.255792"/>
      <!--<inertia ixx="0.23" ixy="0" ixz="0" iyy="0.23" iyz="0" izz="0.4"/>-->
    </inertial>
  </link>
  <gazebo reference="left_wheel_rear">
    <mu1 value="2.0"/>
    <mu2 value="2.0"/>
    <kp value="10000000.0"/>
    <kd value="1.0"/>
    <fdir1 value="0 1 0"/>
    <material>Gazebo/Blue</material>
  </gazebo>
  <joint name="left_wheel_rear_rotate" type="continuous">
    <parent link="chassis"/>
    <child link="left_wheel_rear"/>
    <origin rpy="0 0 0" xyz="-0.8765 0.7115 0.292"/>
    <axis rpy="0 0 0" xyz="0 1 0"/>
    <limit effort="0" velocity="0"/>
    <dynamics damping="0.0" friction="0.0"/>
  </joint>
  <gazebo>
    <plugin filename="libgazebo_ros_control.so" name="gazebo_ros_control">
      <robotNamespace>/ack</robotNamespace>
      <legacyModeNS>true</legacyModeNS>
    </plugin>
  </gazebo>
  <!-- Camera -->
  <!-- You can adjust the camera angle with the p in rpy, measured in radians. -->
  <!-- You can also increate the height of the camera by adding a number, in meters, -->
  <!-- to the z in xyz. For example, to simulate a camera mounted on a 1/2 meter post, -->
  <!-- we can replace the z value with ${wheelRadius+chassisHeight+0.5} -->
  <joint name="camera_joint" type="fixed">
    <origin rpy="0 1.0 0" xyz="0.8765 0 1.292"/>
    <parent link="chassis"/>
    <child link="camera"/>
  </joint>
  <link name="camera">
    <collision>
      <origin rpy="0 0 0" xyz="0 0 0"/>
      <geometry>
        <box size=".05 .05 .05"/>
      </geometry>
    </collision>
    <visual>
      <origin rpy="0 0 0" xyz="0 0 0"/>
      <geometry>
        <box size=".05 .05 .05"/>
      </geometry>
      <material name="blue"/>
    </visual>
    <inertial>
      <mass value="0.05"/>
      <origin rpy="0 0 0" xyz="0 0 0"/>
      <inertia ixx="2.08333333333e-05" ixy="0" ixz="0" iyy="2.08333333333e-05" iyz="0" izz="2.08333333333e-05"/>
    </inertial>
  </link>
  <gazebo reference="camera">
    <material>Gazebo/Blue</material>
    <sensor name="camera1" type="camera">
      <update_rate>30.0</update_rate>
      <camera name="head">
        <horizontal_fov>1.3962634</horizontal_fov>
        <image>
          <width>1600</width>
          <height>1600</height>
          <format>R8G8B8</format>
        </image>
        <clip>
          <near>0.02</near>
          <far>300</far>
        </clip>
      </camera>
      <plugin filename="libgazebo_ros_camera.so" name="camera_controller">
        <alwaysOn>true</alwaysOn>
        <updateRate>0.0</updateRate>
        <cameraName>camera1</cameraName>
        <imageTopicName>image_raw</imageTopicName>
        <cameraInfoTopicName>camera_info</cameraInfoTopicName>
        <frameName>camera_link</frameName>
        <hackBaseline>0.07</hackBaseline>
        <distortionK1>0.0</distortionK1>
        <distortionK2>0.0</distortionK2>
        <distortionK3>0.0</distortionK3>
        <distortionT1>0.0</distortionT1>
        <distortionT2>0.0</distortionT2>
      </plugin>
    </sensor>
  </gazebo>
  <joint name="velodyne_base_mount_joint" type="fixed">
    <origin rpy="0 0 0" xyz="0 0 0.025"/>
    <parent link="mount"/>
    <child link="velodyne_base_link"/>
  </joint>
  <link name="velodyne_base_link">
    <inertial>
      <mass value="0.1"/>
      <origin xyz="0 0 0"/>
      <inertia ixx="0.1" ixy="0" ixz="0" iyy="0.1" iyz="0" izz="0.1"/>
    </inertial>
    <visual>
      <geometry>
        <mesh filename="package://velodyne_description/meshes/VLP16_base_1.dae"/>
      </geometry>
    </visual>
    <visual>
      <geometry>
        <mesh filename="package://velodyne_description/meshes/VLP16_base_2.dae"/>
      </geometry>
    </visual>
    <collision>
      <origin rpy="0 0 0" xyz="0 0 0.03585"/>
      <geometry>
        <cylinder length="0.0717" radius="0.0516"/>
      </geometry>
    </collision>
  </link>
  <joint name="velodyne_base_scan_joint" type="fixed">
    <origin rpy="0 0 0" xyz="0 0 0.0377"/>
    <parent link="velodyne_base_link"/>
    <child link="velodyne"/>
  </joint>
  <link name="velodyne">
    <inertial>
      <mass value="0.1"/>
      <origin xyz="0 0 0"/>
      <inertia ixx="0.1" ixy="0" ixz="0" iyy="0.1" iyz="0" izz="0.1"/>
    </inertial>
    <visual>
      <origin xyz="0 0 -0.0377"/>
      <geometry>
        <mesh filename="package://velodyne_description/meshes/VLP16_scan.dae"/>
      </geometry>
    </visual>
  </link>
  <!-- Gazebo requires the velodyne_gazebo_plugins package -->
  <gazebo reference="velodyne">
    <sensor name="velodyne-VLP16" type="ray">
      <pose>0 0 0 0 0 0</pose>
      <visualize>false</visualize>
      <update_rate>10</update_rate>
      <ray>
        <scan>
          <horizontal>
            <samples>1875</samples>
            <resolution>1</resolution>
            <min_angle>-3.14159265359</min_angle>
            <max_angle> 3.14159265359</max_angle>
          </horizontal>
          <vertical>
            <samples>16</samples>
            <resolution>1</resolution>
            <min_angle>-0.261799387799</min_angle>
            <max_angle> 0.261799387799</max_angle>
          </vertical>
        </scan>
        <range>
          <min>0.055</min>
          <max>140.0</max>
          <resolution>0.001</resolution>
        </range>
        <noise>
          <type>gaussian</type>
          <mean>0.0</mean>
          <stddev>0.0</stddev>
        </noise>
      </ray>
      <plugin filename="libgazebo_ros_velodyne_laser.so" name="gazebo_ros_laser_controller">
        <topicName>/velodyne_points</topicName>
        <frameName>velodyne</frameName>
        <min_range>0.9</min_range>
        <max_range>130.0</max_range>
        <gaussianNoise>0.008</gaussianNoise>
      </plugin>
    </sensor>
  </gazebo>
  <joint name="mount" type="fixed">
    <parent link="chassis"/>
    <child link="mount"/>
    <origin rpy="0 0 0" xyz="0 0 1"/>
  </joint>
  <link name="mount">
    <visual>
      <geometry>
        <box size="0.05 0.05 0.05"/>
      </geometry>
    </visual>
    <collision>
      <geometry>
        <box size="0.05 0.05 0.05"/>
      </geometry>
    </collision>
    <inertial>
      <origin xyz="0 0 0"/>
      <mass value="1"/>
      <inertia ixx="1.0" ixy="0.0" ixz="0.0" iyy="1.0" iyz="0.0" izz="1.0"/>
    </inertial>
  </link>
</robot>

